2018-03-23 19:31:24,928 ERROR: Exception on /edit_profile [POST] [in C:\Users\cmill\Anaconda3\envs\microblog\lib\site-packages\flask\app.py:1560]
Traceback (most recent call last):
  File "C:\Users\cmill\Anaconda3\envs\microblog\lib\site-packages\sqlalchemy\engine\base.py", line 1193, in _execute_context
    context)
  File "C:\Users\cmill\Anaconda3\envs\microblog\lib\site-packages\sqlalchemy\engine\default.py", line 507, in do_execute
    cursor.execute(statement, parameters)
sqlite3.IntegrityError: UNIQUE constraint failed: user.username

The above exception was the direct cause of the following exception:

Traceback (most recent call last):
  File "C:\Users\cmill\Anaconda3\envs\microblog\lib\site-packages\flask\app.py", line 1982, in wsgi_app
    response = self.full_dispatch_request()
  File "C:\Users\cmill\Anaconda3\envs\microblog\lib\site-packages\flask\app.py", line 1614, in full_dispatch_request
    rv = self.handle_user_exception(e)
  File "C:\Users\cmill\Anaconda3\envs\microblog\lib\site-packages\flask\app.py", line 1517, in handle_user_exception
    reraise(exc_type, exc_value, tb)
  File "C:\Users\cmill\Anaconda3\envs\microblog\lib\site-packages\flask\_compat.py", line 33, in reraise
    raise value
  File "C:\Users\cmill\Anaconda3\envs\microblog\lib\site-packages\flask\app.py", line 1612, in full_dispatch_request
    rv = self.dispatch_request()
  File "C:\Users\cmill\Anaconda3\envs\microblog\lib\site-packages\flask\app.py", line 1598, in dispatch_request
    return self.view_functions[rule.endpoint](**req.view_args)
  File "C:\Users\cmill\Anaconda3\envs\microblog\lib\site-packages\flask_login\utils.py", line 228, in decorated_view
    return func(*args, **kwargs)
  File "C:\Users\cmill\Desktop\Programming\microblog\app\routes.py", line 84, in edit_profile
    db.session.commit()
  File "C:\Users\cmill\Anaconda3\envs\microblog\lib\site-packages\sqlalchemy\orm\scoping.py", line 153, in do
    return getattr(self.registry(), name)(*args, **kwargs)
  File "C:\Users\cmill\Anaconda3\envs\microblog\lib\site-packages\sqlalchemy\orm\session.py", line 943, in commit
    self.transaction.commit()
  File "C:\Users\cmill\Anaconda3\envs\microblog\lib\site-packages\sqlalchemy\orm\session.py", line 467, in commit
    self._prepare_impl()
  File "C:\Users\cmill\Anaconda3\envs\microblog\lib\site-packages\sqlalchemy\orm\session.py", line 447, in _prepare_impl
    self.session.flush()
  File "C:\Users\cmill\Anaconda3\envs\microblog\lib\site-packages\sqlalchemy\orm\session.py", line 2254, in flush
    self._flush(objects)
  File "C:\Users\cmill\Anaconda3\envs\microblog\lib\site-packages\sqlalchemy\orm\session.py", line 2380, in _flush
    transaction.rollback(_capture_exception=True)
  File "C:\Users\cmill\Anaconda3\envs\microblog\lib\site-packages\sqlalchemy\util\langhelpers.py", line 66, in __exit__
    compat.reraise(exc_type, exc_value, exc_tb)
  File "C:\Users\cmill\Anaconda3\envs\microblog\lib\site-packages\sqlalchemy\util\compat.py", line 187, in reraise
    raise value
  File "C:\Users\cmill\Anaconda3\envs\microblog\lib\site-packages\sqlalchemy\orm\session.py", line 2344, in _flush
    flush_context.execute()
  File "C:\Users\cmill\Anaconda3\envs\microblog\lib\site-packages\sqlalchemy\orm\unitofwork.py", line 391, in execute
    rec.execute(self)
  File "C:\Users\cmill\Anaconda3\envs\microblog\lib\site-packages\sqlalchemy\orm\unitofwork.py", line 556, in execute
    uow
  File "C:\Users\cmill\Anaconda3\envs\microblog\lib\site-packages\sqlalchemy\orm\persistence.py", line 177, in save_obj
    mapper, table, update)
  File "C:\Users\cmill\Anaconda3\envs\microblog\lib\site-packages\sqlalchemy\orm\persistence.py", line 768, in _emit_update_statements
    execute(statement, multiparams)
  File "C:\Users\cmill\Anaconda3\envs\microblog\lib\site-packages\sqlalchemy\engine\base.py", line 948, in execute
    return meth(self, multiparams, params)
  File "C:\Users\cmill\Anaconda3\envs\microblog\lib\site-packages\sqlalchemy\sql\elements.py", line 269, in _execute_on_connection
    return connection._execute_clauseelement(self, multiparams, params)
  File "C:\Users\cmill\Anaconda3\envs\microblog\lib\site-packages\sqlalchemy\engine\base.py", line 1060, in _execute_clauseelement
    compiled_sql, distilled_params
  File "C:\Users\cmill\Anaconda3\envs\microblog\lib\site-packages\sqlalchemy\engine\base.py", line 1200, in _execute_context
    context)
  File "C:\Users\cmill\Anaconda3\envs\microblog\lib\site-packages\sqlalchemy\engine\base.py", line 1413, in _handle_dbapi_exception
    exc_info
  File "C:\Users\cmill\Anaconda3\envs\microblog\lib\site-packages\sqlalchemy\util\compat.py", line 203, in raise_from_cause
    reraise(type(exception), exception, tb=exc_tb, cause=cause)
  File "C:\Users\cmill\Anaconda3\envs\microblog\lib\site-packages\sqlalchemy\util\compat.py", line 186, in reraise
    raise value.with_traceback(tb)
  File "C:\Users\cmill\Anaconda3\envs\microblog\lib\site-packages\sqlalchemy\engine\base.py", line 1193, in _execute_context
    context)
  File "C:\Users\cmill\Anaconda3\envs\microblog\lib\site-packages\sqlalchemy\engine\default.py", line 507, in do_execute
    cursor.execute(statement, parameters)
sqlalchemy.exc.IntegrityError: (sqlite3.IntegrityError) UNIQUE constraint failed: user.username [SQL: 'UPDATE user SET username=?, about_me=? WHERE user.id = ?'] [parameters: ('susan', 'Avid traveler, and programmer, striving to make the world a better place.', 2)] (Background on this error at: http://sqlalche.me/e/gkpj)
